
Mon, 10/11/21, 10:40:14 AM: 
    Non-fatal:
        Authorization file not found!
        Continuing without authentification...

Mon, 10/11/21, 10:42:16 AM: 
            Non-fatal:
                Authorization file not found!
                Continuing without authentification...

Mon, 10/11/21, 10:42:50 AM: 
            Non-fatal:
                Authorization file not found!
                Continuing without authentification...

Mon, 10/11/21, 10:43:01 AM: 
            Non-fatal:
                Authorization file not found!
                Continuing without authentification...

Mon, 10/11/21, 10:43:03 AM: 
Non-fatal:
    Authorization file not found!
    Continuing without authentification...

Mon, 10/11/21, 10:43:09 AM: 
    Non-fatal:
        Authorization file not found!
        Continuing without authentification...

Mon, 10/11/21, 10:43:36 AM: 
    Authorization file not found!
    Continuing without authentification...

Mon, 10/11/21, 10:46:52 AM: 
    Invalid personal access token!
    Please see https://github.com/settings/tokens
    to create a token with "repo" permissions!
    Continuing without authentification...
Traceback (most recent call last):
  File "/home/j/catalog/osl/new_extractor/extractor.py", line 55, in verify_auth
    self.sesh.get_user().name
  File "/home/j/.local/lib/python3.9/site-packages/github/AuthenticatedUser.py", line 239, in name
    self._completeIfNotSet(self._name)
  File "/home/j/.local/lib/python3.9/site-packages/github/GithubObject.py", line 297, in _completeIfNotSet
    self._completeIfNeeded()
  File "/home/j/.local/lib/python3.9/site-packages/github/GithubObject.py", line 301, in _completeIfNeeded
    self.__complete()
  File "/home/j/.local/lib/python3.9/site-packages/github/GithubObject.py", line 308, in __complete
    headers, data = self._requester.requestJsonAndCheck("GET", self._url.value)
  File "/home/j/.local/lib/python3.9/site-packages/github/Requester.py", line 353, in requestJsonAndCheck
    return self.__check(
  File "/home/j/.local/lib/python3.9/site-packages/github/Requester.py", line 378, in __check
    raise self.__createException(status, responseHeaders, output)
github.GithubException.BadCredentialsException: 401 {"message": "Bad credentials", "documentation_url": "https://docs.github.com/rest"}
